[2024-06-30T06:21:53.763+0000] {local_task_job_runner.py:120} INFO - ::group::Pre task execution logs
[2024-06-30T06:21:53.836+0000] {taskinstance.py:2076} INFO - Dependencies all met for dep_context=non-requeueable deps ti=<TaskInstance: DAG_python_operator_V1.get_name manual__2024-06-30T06:21:52.283623+00:00 [queued]>
[2024-06-30T06:21:53.859+0000] {taskinstance.py:2076} INFO - Dependencies all met for dep_context=requeueable deps ti=<TaskInstance: DAG_python_operator_V1.get_name manual__2024-06-30T06:21:52.283623+00:00 [queued]>
[2024-06-30T06:21:53.860+0000] {taskinstance.py:2306} INFO - Starting attempt 1 of 6
[2024-06-30T06:21:53.889+0000] {taskinstance.py:2330} INFO - Executing <Task(PythonOperator): get_name> on 2024-06-30 06:21:52.283623+00:00
[2024-06-30T06:21:53.899+0000] {standard_task_runner.py:90} INFO - Running: ['***', 'tasks', 'run', 'DAG_python_operator_V1', 'get_name', 'manual__2024-06-30T06:21:52.283623+00:00', '--job-id', '28', '--raw', '--subdir', 'DAGS_FOLDER/dag_python_operator.py', '--cfg-path', '/tmp/tmp5sqauxgg']
[2024-06-30T06:21:53.908+0000] {standard_task_runner.py:91} INFO - Job 28: Subtask get_name
[2024-06-30T06:21:53.916+0000] {logging_mixin.py:188} WARNING - /home/***/.local/lib/python3.12/site-packages/***/task/task_runner/standard_task_runner.py:61 DeprecationWarning: This process (pid=2790) is multi-threaded, use of fork() may lead to deadlocks in the child.
[2024-06-30T06:21:53.918+0000] {standard_task_runner.py:63} INFO - Started process 2791 to run task
[2024-06-30T06:21:53.987+0000] {task_command.py:426} INFO - Running <TaskInstance: DAG_python_operator_V1.get_name manual__2024-06-30T06:21:52.283623+00:00 [running]> on host cf712bcdd57c
[2024-06-30T06:21:54.148+0000] {taskinstance.py:2648} INFO - Exporting env vars: AIRFLOW_CTX_DAG_OWNER='bavenraj' AIRFLOW_CTX_DAG_ID='DAG_python_operator_V1' AIRFLOW_CTX_TASK_ID='get_name' AIRFLOW_CTX_EXECUTION_DATE='2024-06-30T06:21:52.283623+00:00' AIRFLOW_CTX_TRY_NUMBER='1' AIRFLOW_CTX_DAG_RUN_ID='manual__2024-06-30T06:21:52.283623+00:00'
[2024-06-30T06:21:54.151+0000] {taskinstance.py:430} INFO - ::endgroup::
[2024-06-30T06:21:54.171+0000] {taskinstance.py:441} INFO - ::group::Post task execution logs
[2024-06-30T06:21:54.172+0000] {taskinstance.py:2905} ERROR - Task failed with exception
Traceback (most recent call last):
  File "/home/airflow/.local/lib/python3.12/site-packages/airflow/models/taskinstance.py", line 465, in _execute_task
    result = _execute_callable(context=context, **execute_callable_kwargs)
             ^^^^^^^^^^^^^^^^^^^^^^^^^^^^^^^^^^^^^^^^^^^^^^^^^^^^^^^^^^^^^
  File "/home/airflow/.local/lib/python3.12/site-packages/airflow/models/taskinstance.py", line 432, in _execute_callable
    return execute_callable(context=context, **execute_callable_kwargs)
           ^^^^^^^^^^^^^^^^^^^^^^^^^^^^^^^^^^^^^^^^^^^^^^^^^^^^^^^^^^^^
  File "/home/airflow/.local/lib/python3.12/site-packages/airflow/models/baseoperator.py", line 401, in wrapper
    return func(self, *args, **kwargs)
           ^^^^^^^^^^^^^^^^^^^^^^^^^^^
  File "/home/airflow/.local/lib/python3.12/site-packages/airflow/operators/python.py", line 235, in execute
    return_value = self.execute_callable()
                   ^^^^^^^^^^^^^^^^^^^^^^^
  File "/home/airflow/.local/lib/python3.12/site-packages/airflow/operators/python.py", line 252, in execute_callable
    return self.python_callable(*self.op_args, **self.op_kwargs)
           ^^^^^^^^^^^^^^^^^^^^^^^^^^^^^^^^^^^^^^^^^^^^^^^^^^^^^
  File "/opt/airflow/dags/dag_python_operator.py", line 16, in get_name
    ti.xcom_pull(key='first_name', value='Tom')
  File "/home/airflow/.local/lib/python3.12/site-packages/airflow/utils/session.py", line 79, in wrapper
    return func(*args, session=session, **kwargs)
           ^^^^^^^^^^^^^^^^^^^^^^^^^^^^^^^^^^^^^^
TypeError: TaskInstance.xcom_pull() got an unexpected keyword argument 'value'
[2024-06-30T06:21:54.193+0000] {taskinstance.py:1206} INFO - Marking task as UP_FOR_RETRY. dag_id=DAG_python_operator_V1, task_id=get_name, run_id=manual__2024-06-30T06:21:52.283623+00:00, execution_date=20240630T062152, start_date=20240630T062153, end_date=20240630T062154
[2024-06-30T06:21:54.219+0000] {standard_task_runner.py:110} ERROR - Failed to execute job 28 for task get_name (TaskInstance.xcom_pull() got an unexpected keyword argument 'value'; 2791)
[2024-06-30T06:21:54.255+0000] {local_task_job_runner.py:240} INFO - Task exited with return code 1
[2024-06-30T06:21:54.290+0000] {taskinstance.py:3503} INFO - 0 downstream tasks scheduled from follow-on schedule check
[2024-06-30T06:21:54.293+0000] {local_task_job_runner.py:222} INFO - ::endgroup::
