[2024-06-30T07:06:14.087+0000] {local_task_job_runner.py:120} INFO - ::group::Pre task execution logs
[2024-06-30T07:06:14.179+0000] {taskinstance.py:2076} INFO - Dependencies all met for dep_context=non-requeueable deps ti=<TaskInstance: DAG_catchup_backfill.task1 manual__2024-06-30T07:04:11.534052+00:00 [queued]>
[2024-06-30T07:06:14.203+0000] {taskinstance.py:2076} INFO - Dependencies all met for dep_context=requeueable deps ti=<TaskInstance: DAG_catchup_backfill.task1 manual__2024-06-30T07:04:11.534052+00:00 [queued]>
[2024-06-30T07:06:14.205+0000] {taskinstance.py:2306} INFO - Starting attempt 2 of 6
[2024-06-30T07:06:14.239+0000] {taskinstance.py:2330} INFO - Executing <Task(BashOperator): task1> on 2024-06-30 07:04:11.534052+00:00
[2024-06-30T07:06:14.252+0000] {standard_task_runner.py:90} INFO - Running: ['***', 'tasks', 'run', 'DAG_catchup_backfill', 'task1', 'manual__2024-06-30T07:04:11.534052+00:00', '--job-id', '46', '--raw', '--subdir', 'DAGS_FOLDER/dag_catchup_backfill.py', '--cfg-path', '/tmp/tmpxnkdzdsi']
[2024-06-30T07:06:14.256+0000] {standard_task_runner.py:91} INFO - Job 46: Subtask task1
[2024-06-30T07:06:14.264+0000] {logging_mixin.py:188} WARNING - /home/***/.local/lib/python3.12/site-packages/***/task/task_runner/standard_task_runner.py:61 DeprecationWarning: This process (pid=4507) is multi-threaded, use of fork() may lead to deadlocks in the child.
[2024-06-30T07:06:14.265+0000] {standard_task_runner.py:63} INFO - Started process 4508 to run task
[2024-06-30T07:06:14.333+0000] {task_command.py:426} INFO - Running <TaskInstance: DAG_catchup_backfill.task1 manual__2024-06-30T07:04:11.534052+00:00 [running]> on host cf712bcdd57c
[2024-06-30T07:06:14.449+0000] {taskinstance.py:2648} INFO - Exporting env vars: AIRFLOW_CTX_DAG_OWNER='Bavenraj' AIRFLOW_CTX_DAG_ID='DAG_catchup_backfill' AIRFLOW_CTX_TASK_ID='task1' AIRFLOW_CTX_EXECUTION_DATE='2024-06-30T07:04:11.534052+00:00' AIRFLOW_CTX_TRY_NUMBER='2' AIRFLOW_CTX_DAG_RUN_ID='manual__2024-06-30T07:04:11.534052+00:00'
[2024-06-30T07:06:14.451+0000] {taskinstance.py:430} INFO - ::endgroup::
[2024-06-30T07:06:14.471+0000] {subprocess.py:63} INFO - Tmp dir root location: /tmp
[2024-06-30T07:06:14.473+0000] {subprocess.py:75} INFO - Running command: ['/usr/bin/bash', '-c', 'this is the simple bash command']
[2024-06-30T07:06:14.491+0000] {subprocess.py:86} INFO - Output:
[2024-06-30T07:06:14.496+0000] {subprocess.py:93} INFO - /usr/bin/bash: line 1: this: command not found
[2024-06-30T07:06:14.498+0000] {subprocess.py:97} INFO - Command exited with return code 127
[2024-06-30T07:06:14.499+0000] {taskinstance.py:441} INFO - ::group::Post task execution logs
[2024-06-30T07:06:14.515+0000] {taskinstance.py:2905} ERROR - Task failed with exception
Traceback (most recent call last):
  File "/home/airflow/.local/lib/python3.12/site-packages/airflow/models/taskinstance.py", line 465, in _execute_task
    result = _execute_callable(context=context, **execute_callable_kwargs)
             ^^^^^^^^^^^^^^^^^^^^^^^^^^^^^^^^^^^^^^^^^^^^^^^^^^^^^^^^^^^^^
  File "/home/airflow/.local/lib/python3.12/site-packages/airflow/models/taskinstance.py", line 432, in _execute_callable
    return execute_callable(context=context, **execute_callable_kwargs)
           ^^^^^^^^^^^^^^^^^^^^^^^^^^^^^^^^^^^^^^^^^^^^^^^^^^^^^^^^^^^^
  File "/home/airflow/.local/lib/python3.12/site-packages/airflow/models/baseoperator.py", line 401, in wrapper
    return func(self, *args, **kwargs)
           ^^^^^^^^^^^^^^^^^^^^^^^^^^^
  File "/home/airflow/.local/lib/python3.12/site-packages/airflow/operators/bash.py", line 243, in execute
    raise AirflowException(
airflow.exceptions.AirflowException: Bash command failed. The command returned a non-zero exit code 127.
[2024-06-30T07:06:14.522+0000] {taskinstance.py:1206} INFO - Marking task as UP_FOR_RETRY. dag_id=DAG_catchup_backfill, task_id=task1, run_id=manual__2024-06-30T07:04:11.534052+00:00, execution_date=20240630T070411, start_date=20240630T070614, end_date=20240630T070614
[2024-06-30T07:06:14.547+0000] {standard_task_runner.py:110} ERROR - Failed to execute job 46 for task task1 (Bash command failed. The command returned a non-zero exit code 127.; 4508)
[2024-06-30T07:06:14.601+0000] {local_task_job_runner.py:240} INFO - Task exited with return code 1
[2024-06-30T07:06:14.627+0000] {taskinstance.py:3503} INFO - 0 downstream tasks scheduled from follow-on schedule check
[2024-06-30T07:06:14.630+0000] {local_task_job_runner.py:222} INFO - ::endgroup::
