[2024-06-30T07:03:03.237+0000] {local_task_job_runner.py:120} INFO - ::group::Pre task execution logs
[2024-06-30T07:03:03.287+0000] {taskinstance.py:2076} INFO - Dependencies all met for dep_context=non-requeueable deps ti=<TaskInstance: DAG_catchup_backfill.task1 manual__2024-06-30T07:03:01.922447+00:00 [queued]>
[2024-06-30T07:03:03.301+0000] {taskinstance.py:2076} INFO - Dependencies all met for dep_context=requeueable deps ti=<TaskInstance: DAG_catchup_backfill.task1 manual__2024-06-30T07:03:01.922447+00:00 [queued]>
[2024-06-30T07:03:03.302+0000] {taskinstance.py:2306} INFO - Starting attempt 1 of 6
[2024-06-30T07:03:03.323+0000] {taskinstance.py:2330} INFO - Executing <Task(BashOperator): task1> on 2024-06-30 07:03:01.922447+00:00
[2024-06-30T07:03:03.332+0000] {standard_task_runner.py:90} INFO - Running: ['***', 'tasks', 'run', 'DAG_catchup_backfill', 'task1', 'manual__2024-06-30T07:03:01.922447+00:00', '--job-id', '44', '--raw', '--subdir', 'DAGS_FOLDER/dag_catchup_backfill.py', '--cfg-path', '/tmp/tmpo51pu3y9']
[2024-06-30T07:03:03.335+0000] {standard_task_runner.py:91} INFO - Job 44: Subtask task1
[2024-06-30T07:03:03.339+0000] {logging_mixin.py:188} WARNING - /home/***/.local/lib/python3.12/site-packages/***/task/task_runner/standard_task_runner.py:61 DeprecationWarning: This process (pid=4324) is multi-threaded, use of fork() may lead to deadlocks in the child.
[2024-06-30T07:03:03.340+0000] {standard_task_runner.py:63} INFO - Started process 4325 to run task
[2024-06-30T07:03:03.396+0000] {task_command.py:426} INFO - Running <TaskInstance: DAG_catchup_backfill.task1 manual__2024-06-30T07:03:01.922447+00:00 [running]> on host cf712bcdd57c
[2024-06-30T07:03:03.507+0000] {taskinstance.py:2648} INFO - Exporting env vars: AIRFLOW_CTX_DAG_OWNER='Bavenraj' AIRFLOW_CTX_DAG_ID='DAG_catchup_backfill' AIRFLOW_CTX_TASK_ID='task1' AIRFLOW_CTX_EXECUTION_DATE='2024-06-30T07:03:01.922447+00:00' AIRFLOW_CTX_TRY_NUMBER='1' AIRFLOW_CTX_DAG_RUN_ID='manual__2024-06-30T07:03:01.922447+00:00'
[2024-06-30T07:03:03.511+0000] {taskinstance.py:430} INFO - ::endgroup::
[2024-06-30T07:03:03.555+0000] {subprocess.py:63} INFO - Tmp dir root location: /tmp
[2024-06-30T07:03:03.558+0000] {subprocess.py:75} INFO - Running command: ['/usr/bin/bash', '-c', 'this is the simple bash command']
[2024-06-30T07:03:03.573+0000] {subprocess.py:86} INFO - Output:
[2024-06-30T07:03:03.578+0000] {subprocess.py:93} INFO - /usr/bin/bash: line 1: this: command not found
[2024-06-30T07:03:03.579+0000] {subprocess.py:97} INFO - Command exited with return code 127
[2024-06-30T07:03:03.581+0000] {taskinstance.py:441} INFO - ::group::Post task execution logs
[2024-06-30T07:03:03.599+0000] {taskinstance.py:2905} ERROR - Task failed with exception
Traceback (most recent call last):
  File "/home/airflow/.local/lib/python3.12/site-packages/airflow/models/taskinstance.py", line 465, in _execute_task
    result = _execute_callable(context=context, **execute_callable_kwargs)
             ^^^^^^^^^^^^^^^^^^^^^^^^^^^^^^^^^^^^^^^^^^^^^^^^^^^^^^^^^^^^^
  File "/home/airflow/.local/lib/python3.12/site-packages/airflow/models/taskinstance.py", line 432, in _execute_callable
    return execute_callable(context=context, **execute_callable_kwargs)
           ^^^^^^^^^^^^^^^^^^^^^^^^^^^^^^^^^^^^^^^^^^^^^^^^^^^^^^^^^^^^
  File "/home/airflow/.local/lib/python3.12/site-packages/airflow/models/baseoperator.py", line 401, in wrapper
    return func(self, *args, **kwargs)
           ^^^^^^^^^^^^^^^^^^^^^^^^^^^
  File "/home/airflow/.local/lib/python3.12/site-packages/airflow/operators/bash.py", line 243, in execute
    raise AirflowException(
airflow.exceptions.AirflowException: Bash command failed. The command returned a non-zero exit code 127.
[2024-06-30T07:03:03.610+0000] {taskinstance.py:1206} INFO - Marking task as UP_FOR_RETRY. dag_id=DAG_catchup_backfill, task_id=task1, run_id=manual__2024-06-30T07:03:01.922447+00:00, execution_date=20240630T070301, start_date=20240630T070303, end_date=20240630T070303
[2024-06-30T07:03:03.640+0000] {standard_task_runner.py:110} ERROR - Failed to execute job 44 for task task1 (Bash command failed. The command returned a non-zero exit code 127.; 4325)
[2024-06-30T07:03:03.676+0000] {local_task_job_runner.py:240} INFO - Task exited with return code 1
[2024-06-30T07:03:03.703+0000] {taskinstance.py:3503} INFO - 0 downstream tasks scheduled from follow-on schedule check
[2024-06-30T07:03:03.707+0000] {local_task_job_runner.py:222} INFO - ::endgroup::
